[2022-01-11 17:20:08,997] {taskinstance.py:1032} INFO - Dependencies all met for <TaskInstance: stocks_dag.sql_connect_ manual__2022-01-11T17:18:06.609179+00:00 [queued]>
[2022-01-11 17:20:09,009] {taskinstance.py:1032} INFO - Dependencies all met for <TaskInstance: stocks_dag.sql_connect_ manual__2022-01-11T17:18:06.609179+00:00 [queued]>
[2022-01-11 17:20:09,010] {taskinstance.py:1238} INFO - 
--------------------------------------------------------------------------------
[2022-01-11 17:20:09,011] {taskinstance.py:1239} INFO - Starting attempt 2 of 4
[2022-01-11 17:20:09,011] {taskinstance.py:1240} INFO - 
--------------------------------------------------------------------------------
[2022-01-11 17:20:09,024] {taskinstance.py:1259} INFO - Executing <Task(PythonOperator): sql_connect_> on 2022-01-11 17:18:06.609179+00:00
[2022-01-11 17:20:09,030] {standard_task_runner.py:52} INFO - Started process 572 to run task
[2022-01-11 17:20:09,034] {standard_task_runner.py:76} INFO - Running: ['***', 'tasks', 'run', 'stocks_dag', 'sql_connect_', 'manual__2022-01-11T17:18:06.609179+00:00', '--job-id', '372', '--raw', '--subdir', 'DAGS_FOLDER/stocks_dag.py', '--cfg-path', '/tmp/tmplt445cbk', '--error-file', '/tmp/tmp35hd8se2']
[2022-01-11 17:20:09,035] {standard_task_runner.py:77} INFO - Job 372: Subtask sql_connect_
[2022-01-11 17:20:09,097] {logging_mixin.py:109} INFO - Running <TaskInstance: stocks_dag.sql_connect_ manual__2022-01-11T17:18:06.609179+00:00 [running]> on host 10d1e29787a9
[2022-01-11 17:20:09,146] {taskinstance.py:1426} INFO - Exporting the following env vars:
AIRFLOW_CTX_DAG_EMAIL=mcgaritym@gmail.com
AIRFLOW_CTX_DAG_OWNER=***
AIRFLOW_CTX_DAG_ID=stocks_dag
AIRFLOW_CTX_TASK_ID=sql_connect_
AIRFLOW_CTX_EXECUTION_DATE=2022-01-11T17:18:06.609179+00:00
AIRFLOW_CTX_DAG_RUN_ID=manual__2022-01-11T17:18:06.609179+00:00
[2022-01-11 17:20:09,148] {taskinstance.py:1700} ERROR - Task failed with exception
Traceback (most recent call last):
  File "/home/airflow/.local/lib/python3.7/site-packages/airflow/models/taskinstance.py", line 1329, in _run_raw_task
    self._execute_task_with_callbacks(context)
  File "/home/airflow/.local/lib/python3.7/site-packages/airflow/models/taskinstance.py", line 1455, in _execute_task_with_callbacks
    result = self._execute_task(context, self.task)
  File "/home/airflow/.local/lib/python3.7/site-packages/airflow/models/taskinstance.py", line 1511, in _execute_task
    result = execute_callable(context=context)
  File "/home/airflow/.local/lib/python3.7/site-packages/airflow/operators/python.py", line 174, in execute
    return_value = self.execute_callable()
  File "/home/airflow/.local/lib/python3.7/site-packages/airflow/operators/python.py", line 185, in execute_callable
    return self.python_callable(*self.op_args, **self.op_kwargs)
  File "/opt/airflow/dags/sql_connect.py", line 15, in sql_connect_1
    connection_1 = mysql.connector.connect(host=host, user=user, password=pwd, port=port)
NameError: name 'host' is not defined
[2022-01-11 17:20:09,163] {taskinstance.py:1277} INFO - Marking task as UP_FOR_RETRY. dag_id=stocks_dag, task_id=sql_connect_, execution_date=20220111T171806, start_date=20220111T172008, end_date=20220111T172009
[2022-01-11 17:20:09,176] {standard_task_runner.py:92} ERROR - Failed to execute job 372 for task sql_connect_
Traceback (most recent call last):
  File "/home/airflow/.local/lib/python3.7/site-packages/airflow/task/task_runner/standard_task_runner.py", line 85, in _start_by_fork
    args.func(args, dag=self.dag)
  File "/home/airflow/.local/lib/python3.7/site-packages/airflow/cli/cli_parser.py", line 48, in command
    return func(*args, **kwargs)
  File "/home/airflow/.local/lib/python3.7/site-packages/airflow/utils/cli.py", line 92, in wrapper
    return f(*args, **kwargs)
  File "/home/airflow/.local/lib/python3.7/site-packages/airflow/cli/commands/task_command.py", line 298, in task_run
    _run_task_by_selected_method(args, dag, ti)
  File "/home/airflow/.local/lib/python3.7/site-packages/airflow/cli/commands/task_command.py", line 107, in _run_task_by_selected_method
    _run_raw_task(args, ti)
  File "/home/airflow/.local/lib/python3.7/site-packages/airflow/cli/commands/task_command.py", line 184, in _run_raw_task
    error_file=args.error_file,
  File "/home/airflow/.local/lib/python3.7/site-packages/airflow/utils/session.py", line 70, in wrapper
    return func(*args, session=session, **kwargs)
  File "/home/airflow/.local/lib/python3.7/site-packages/airflow/models/taskinstance.py", line 1329, in _run_raw_task
    self._execute_task_with_callbacks(context)
  File "/home/airflow/.local/lib/python3.7/site-packages/airflow/models/taskinstance.py", line 1455, in _execute_task_with_callbacks
    result = self._execute_task(context, self.task)
  File "/home/airflow/.local/lib/python3.7/site-packages/airflow/models/taskinstance.py", line 1511, in _execute_task
    result = execute_callable(context=context)
  File "/home/airflow/.local/lib/python3.7/site-packages/airflow/operators/python.py", line 174, in execute
    return_value = self.execute_callable()
  File "/home/airflow/.local/lib/python3.7/site-packages/airflow/operators/python.py", line 185, in execute_callable
    return self.python_callable(*self.op_args, **self.op_kwargs)
  File "/opt/airflow/dags/sql_connect.py", line 15, in sql_connect_1
    connection_1 = mysql.connector.connect(host=host, user=user, password=pwd, port=port)
NameError: name 'host' is not defined
[2022-01-11 17:20:09,209] {local_task_job.py:154} INFO - Task exited with return code 1
[2022-01-11 17:20:09,240] {local_task_job.py:264} INFO - 0 downstream tasks scheduled from follow-on schedule check
