[2022-01-11 16:01:57,633] {taskinstance.py:1032} INFO - Dependencies all met for <TaskInstance: stocks_dag.sql_connect_ manual__2022-01-11T15:57:53.284347+00:00 [queued]>
[2022-01-11 16:01:57,643] {taskinstance.py:1032} INFO - Dependencies all met for <TaskInstance: stocks_dag.sql_connect_ manual__2022-01-11T15:57:53.284347+00:00 [queued]>
[2022-01-11 16:01:57,644] {taskinstance.py:1238} INFO - 
--------------------------------------------------------------------------------
[2022-01-11 16:01:57,645] {taskinstance.py:1239} INFO - Starting attempt 3 of 4
[2022-01-11 16:01:57,646] {taskinstance.py:1240} INFO - 
--------------------------------------------------------------------------------
[2022-01-11 16:01:57,658] {taskinstance.py:1259} INFO - Executing <Task(PythonOperator): sql_connect_> on 2022-01-11 15:57:53.284347+00:00
[2022-01-11 16:01:57,663] {standard_task_runner.py:52} INFO - Started process 388 to run task
[2022-01-11 16:01:57,667] {standard_task_runner.py:76} INFO - Running: ['***', 'tasks', 'run', 'stocks_dag', 'sql_connect_', 'manual__2022-01-11T15:57:53.284347+00:00', '--job-id', '182', '--raw', '--subdir', 'DAGS_FOLDER/stocks_dag.py', '--cfg-path', '/tmp/tmp9ip71lf8', '--error-file', '/tmp/tmp0hdr_5bt']
[2022-01-11 16:01:57,669] {standard_task_runner.py:77} INFO - Job 182: Subtask sql_connect_
[2022-01-11 16:01:57,732] {logging_mixin.py:109} INFO - Running <TaskInstance: stocks_dag.sql_connect_ manual__2022-01-11T15:57:53.284347+00:00 [running]> on host b2689cbd0ea6
[2022-01-11 16:01:57,792] {taskinstance.py:1426} INFO - Exporting the following env vars:
AIRFLOW_CTX_DAG_EMAIL=mcgaritym@gmail.com
AIRFLOW_CTX_DAG_OWNER=***
AIRFLOW_CTX_DAG_ID=stocks_dag
AIRFLOW_CTX_TASK_ID=sql_connect_
AIRFLOW_CTX_EXECUTION_DATE=2022-01-11T15:57:53.284347+00:00
AIRFLOW_CTX_DAG_RUN_ID=manual__2022-01-11T15:57:53.284347+00:00
[2022-01-11 16:01:57,803] {taskinstance.py:1700} ERROR - Task failed with exception
Traceback (most recent call last):
  File "/home/airflow/.local/lib/python3.7/site-packages/mysql/connector/connection_cext.py", line 236, in _open_connection
    self._cmysql.connect(**cnx_kwargs)
_mysql_connector.MySQLInterfaceError: Unknown MySQL server host 'db' (-2)

During handling of the above exception, another exception occurred:

Traceback (most recent call last):
  File "/home/airflow/.local/lib/python3.7/site-packages/airflow/models/taskinstance.py", line 1329, in _run_raw_task
    self._execute_task_with_callbacks(context)
  File "/home/airflow/.local/lib/python3.7/site-packages/airflow/models/taskinstance.py", line 1455, in _execute_task_with_callbacks
    result = self._execute_task(context, self.task)
  File "/home/airflow/.local/lib/python3.7/site-packages/airflow/models/taskinstance.py", line 1511, in _execute_task
    result = execute_callable(context=context)
  File "/home/airflow/.local/lib/python3.7/site-packages/airflow/operators/python.py", line 174, in execute
    return_value = self.execute_callable()
  File "/home/airflow/.local/lib/python3.7/site-packages/airflow/operators/python.py", line 185, in execute_callable
    return self.python_callable(*self.op_args, **self.op_kwargs)
  File "/opt/airflow/dags/sql_connect.py", line 15, in sql_connect_1
    connection_1 = mysql.connector.connect(host=host, user=user, password=pwd, port=port)
  File "/home/airflow/.local/lib/python3.7/site-packages/mysql/connector/__init__.py", line 272, in connect
    return CMySQLConnection(*args, **kwargs)
  File "/home/airflow/.local/lib/python3.7/site-packages/mysql/connector/connection_cext.py", line 85, in __init__
    self.connect(**kwargs)
  File "/home/airflow/.local/lib/python3.7/site-packages/mysql/connector/abstracts.py", line 1014, in connect
    self._open_connection()
  File "/home/airflow/.local/lib/python3.7/site-packages/mysql/connector/connection_cext.py", line 242, in _open_connection
    sqlstate=exc.sqlstate)
mysql.connector.errors.DatabaseError: 2005 (HY000): Unknown MySQL server host 'db' (-2)
[2022-01-11 16:01:57,818] {taskinstance.py:1277} INFO - Marking task as UP_FOR_RETRY. dag_id=stocks_dag, task_id=sql_connect_, execution_date=20220111T155753, start_date=20220111T160157, end_date=20220111T160157
[2022-01-11 16:01:57,832] {standard_task_runner.py:92} ERROR - Failed to execute job 182 for task sql_connect_
Traceback (most recent call last):
  File "/home/airflow/.local/lib/python3.7/site-packages/mysql/connector/connection_cext.py", line 236, in _open_connection
    self._cmysql.connect(**cnx_kwargs)
_mysql_connector.MySQLInterfaceError: Unknown MySQL server host 'db' (-2)

During handling of the above exception, another exception occurred:

Traceback (most recent call last):
  File "/home/airflow/.local/lib/python3.7/site-packages/airflow/task/task_runner/standard_task_runner.py", line 85, in _start_by_fork
    args.func(args, dag=self.dag)
  File "/home/airflow/.local/lib/python3.7/site-packages/airflow/cli/cli_parser.py", line 48, in command
    return func(*args, **kwargs)
  File "/home/airflow/.local/lib/python3.7/site-packages/airflow/utils/cli.py", line 92, in wrapper
    return f(*args, **kwargs)
  File "/home/airflow/.local/lib/python3.7/site-packages/airflow/cli/commands/task_command.py", line 298, in task_run
    _run_task_by_selected_method(args, dag, ti)
  File "/home/airflow/.local/lib/python3.7/site-packages/airflow/cli/commands/task_command.py", line 107, in _run_task_by_selected_method
    _run_raw_task(args, ti)
  File "/home/airflow/.local/lib/python3.7/site-packages/airflow/cli/commands/task_command.py", line 184, in _run_raw_task
    error_file=args.error_file,
  File "/home/airflow/.local/lib/python3.7/site-packages/airflow/utils/session.py", line 70, in wrapper
    return func(*args, session=session, **kwargs)
  File "/home/airflow/.local/lib/python3.7/site-packages/airflow/models/taskinstance.py", line 1329, in _run_raw_task
    self._execute_task_with_callbacks(context)
  File "/home/airflow/.local/lib/python3.7/site-packages/airflow/models/taskinstance.py", line 1455, in _execute_task_with_callbacks
    result = self._execute_task(context, self.task)
  File "/home/airflow/.local/lib/python3.7/site-packages/airflow/models/taskinstance.py", line 1511, in _execute_task
    result = execute_callable(context=context)
  File "/home/airflow/.local/lib/python3.7/site-packages/airflow/operators/python.py", line 174, in execute
    return_value = self.execute_callable()
  File "/home/airflow/.local/lib/python3.7/site-packages/airflow/operators/python.py", line 185, in execute_callable
    return self.python_callable(*self.op_args, **self.op_kwargs)
  File "/opt/airflow/dags/sql_connect.py", line 15, in sql_connect_1
    connection_1 = mysql.connector.connect(host=host, user=user, password=pwd, port=port)
  File "/home/airflow/.local/lib/python3.7/site-packages/mysql/connector/__init__.py", line 272, in connect
    return CMySQLConnection(*args, **kwargs)
  File "/home/airflow/.local/lib/python3.7/site-packages/mysql/connector/connection_cext.py", line 85, in __init__
    self.connect(**kwargs)
  File "/home/airflow/.local/lib/python3.7/site-packages/mysql/connector/abstracts.py", line 1014, in connect
    self._open_connection()
  File "/home/airflow/.local/lib/python3.7/site-packages/mysql/connector/connection_cext.py", line 242, in _open_connection
    sqlstate=exc.sqlstate)
mysql.connector.errors.DatabaseError: 2005 (HY000): Unknown MySQL server host 'db' (-2)
[2022-01-11 16:01:57,882] {local_task_job.py:154} INFO - Task exited with return code 1
[2022-01-11 16:01:57,909] {local_task_job.py:264} INFO - 0 downstream tasks scheduled from follow-on schedule check
