[2022-01-10 22:54:59,261] {taskinstance.py:1032} INFO - Dependencies all met for <TaskInstance: stocks_dag.get_tickers_ manual__2022-01-10T22:52:53.508655+00:00 [queued]>
[2022-01-10 22:54:59,271] {taskinstance.py:1032} INFO - Dependencies all met for <TaskInstance: stocks_dag.get_tickers_ manual__2022-01-10T22:52:53.508655+00:00 [queued]>
[2022-01-10 22:54:59,272] {taskinstance.py:1238} INFO - 
--------------------------------------------------------------------------------
[2022-01-10 22:54:59,272] {taskinstance.py:1239} INFO - Starting attempt 2 of 4
[2022-01-10 22:54:59,273] {taskinstance.py:1240} INFO - 
--------------------------------------------------------------------------------
[2022-01-10 22:54:59,285] {taskinstance.py:1259} INFO - Executing <Task(PythonOperator): get_tickers_> on 2022-01-10 22:52:53.508655+00:00
[2022-01-10 22:54:59,290] {standard_task_runner.py:52} INFO - Started process 2467 to run task
[2022-01-10 22:54:59,294] {standard_task_runner.py:76} INFO - Running: ['***', 'tasks', 'run', 'stocks_dag', 'get_tickers_', 'manual__2022-01-10T22:52:53.508655+00:00', '--job-id', '105', '--raw', '--subdir', 'DAGS_FOLDER/stocks_dag.py', '--cfg-path', '/tmp/tmp31g_xe2k', '--error-file', '/tmp/tmpiavkbvkj']
[2022-01-10 22:54:59,295] {standard_task_runner.py:77} INFO - Job 105: Subtask get_tickers_
[2022-01-10 22:54:59,355] {logging_mixin.py:109} INFO - Running <TaskInstance: stocks_dag.get_tickers_ manual__2022-01-10T22:52:53.508655+00:00 [running]> on host 6e02ffb9d96a
[2022-01-10 22:54:59,412] {taskinstance.py:1426} INFO - Exporting the following env vars:
AIRFLOW_CTX_DAG_EMAIL=mcgaritym@gmail.com
AIRFLOW_CTX_DAG_OWNER=***
AIRFLOW_CTX_DAG_ID=stocks_dag
AIRFLOW_CTX_TASK_ID=get_tickers_
AIRFLOW_CTX_EXECUTION_DATE=2022-01-10T22:52:53.508655+00:00
AIRFLOW_CTX_DAG_RUN_ID=manual__2022-01-10T22:52:53.508655+00:00
[2022-01-10 22:54:59,428] {taskinstance.py:1700} ERROR - Task failed with exception
Traceback (most recent call last):
  File "/home/airflow/.local/lib/python3.7/site-packages/selenium/webdriver/common/service.py", line 76, in start
    stdin=PIPE)
  File "/usr/local/lib/python3.7/subprocess.py", line 800, in __init__
    restore_signals, start_new_session)
  File "/usr/local/lib/python3.7/subprocess.py", line 1551, in _execute_child
    raise child_exception_type(errno_num, err_msg, err_filename)
FileNotFoundError: [Errno 2] No such file or directory: 'chromedriver': 'chromedriver'

During handling of the above exception, another exception occurred:

Traceback (most recent call last):
  File "/home/airflow/.local/lib/python3.7/site-packages/airflow/models/taskinstance.py", line 1329, in _run_raw_task
    self._execute_task_with_callbacks(context)
  File "/home/airflow/.local/lib/python3.7/site-packages/airflow/models/taskinstance.py", line 1455, in _execute_task_with_callbacks
    result = self._execute_task(context, self.task)
  File "/home/airflow/.local/lib/python3.7/site-packages/airflow/models/taskinstance.py", line 1511, in _execute_task
    result = execute_callable(context=context)
  File "/home/airflow/.local/lib/python3.7/site-packages/airflow/operators/python.py", line 174, in execute
    return_value = self.execute_callable()
  File "/home/airflow/.local/lib/python3.7/site-packages/airflow/operators/python.py", line 185, in execute_callable
    return self.python_callable(*self.op_args, **self.op_kwargs)
  File "/opt/airflow/dags/get_tickers.py", line 24, in get_tickers
    driver = webdriver.Chrome()
  File "/home/airflow/.local/lib/python3.7/site-packages/selenium/webdriver/chrome/webdriver.py", line 73, in __init__
    self.service.start()
  File "/home/airflow/.local/lib/python3.7/site-packages/selenium/webdriver/common/service.py", line 83, in start
    os.path.basename(self.path), self.start_error_message)
selenium.common.exceptions.WebDriverException: Message: 'chromedriver' executable needs to be in PATH. Please see https://sites.google.com/a/chromium.org/chromedriver/home

[2022-01-10 22:54:59,452] {taskinstance.py:1277} INFO - Marking task as UP_FOR_RETRY. dag_id=stocks_dag, task_id=get_tickers_, execution_date=20220110T225253, start_date=20220110T225459, end_date=20220110T225459
[2022-01-10 22:54:59,475] {standard_task_runner.py:92} ERROR - Failed to execute job 105 for task get_tickers_
Traceback (most recent call last):
  File "/home/airflow/.local/lib/python3.7/site-packages/selenium/webdriver/common/service.py", line 76, in start
    stdin=PIPE)
  File "/usr/local/lib/python3.7/subprocess.py", line 800, in __init__
    restore_signals, start_new_session)
  File "/usr/local/lib/python3.7/subprocess.py", line 1551, in _execute_child
    raise child_exception_type(errno_num, err_msg, err_filename)
FileNotFoundError: [Errno 2] No such file or directory: 'chromedriver': 'chromedriver'

During handling of the above exception, another exception occurred:

Traceback (most recent call last):
  File "/home/airflow/.local/lib/python3.7/site-packages/airflow/task/task_runner/standard_task_runner.py", line 85, in _start_by_fork
    args.func(args, dag=self.dag)
  File "/home/airflow/.local/lib/python3.7/site-packages/airflow/cli/cli_parser.py", line 48, in command
    return func(*args, **kwargs)
  File "/home/airflow/.local/lib/python3.7/site-packages/airflow/utils/cli.py", line 92, in wrapper
    return f(*args, **kwargs)
  File "/home/airflow/.local/lib/python3.7/site-packages/airflow/cli/commands/task_command.py", line 298, in task_run
    _run_task_by_selected_method(args, dag, ti)
  File "/home/airflow/.local/lib/python3.7/site-packages/airflow/cli/commands/task_command.py", line 107, in _run_task_by_selected_method
    _run_raw_task(args, ti)
  File "/home/airflow/.local/lib/python3.7/site-packages/airflow/cli/commands/task_command.py", line 184, in _run_raw_task
    error_file=args.error_file,
  File "/home/airflow/.local/lib/python3.7/site-packages/airflow/utils/session.py", line 70, in wrapper
    return func(*args, session=session, **kwargs)
  File "/home/airflow/.local/lib/python3.7/site-packages/airflow/models/taskinstance.py", line 1329, in _run_raw_task
    self._execute_task_with_callbacks(context)
  File "/home/airflow/.local/lib/python3.7/site-packages/airflow/models/taskinstance.py", line 1455, in _execute_task_with_callbacks
    result = self._execute_task(context, self.task)
  File "/home/airflow/.local/lib/python3.7/site-packages/airflow/models/taskinstance.py", line 1511, in _execute_task
    result = execute_callable(context=context)
  File "/home/airflow/.local/lib/python3.7/site-packages/airflow/operators/python.py", line 174, in execute
    return_value = self.execute_callable()
  File "/home/airflow/.local/lib/python3.7/site-packages/airflow/operators/python.py", line 185, in execute_callable
    return self.python_callable(*self.op_args, **self.op_kwargs)
  File "/opt/airflow/dags/get_tickers.py", line 24, in get_tickers
    driver = webdriver.Chrome()
  File "/home/airflow/.local/lib/python3.7/site-packages/selenium/webdriver/chrome/webdriver.py", line 73, in __init__
    self.service.start()
  File "/home/airflow/.local/lib/python3.7/site-packages/selenium/webdriver/common/service.py", line 83, in start
    os.path.basename(self.path), self.start_error_message)
selenium.common.exceptions.WebDriverException: Message: 'chromedriver' executable needs to be in PATH. Please see https://sites.google.com/a/chromium.org/chromedriver/home

[2022-01-10 22:54:59,508] {local_task_job.py:154} INFO - Task exited with return code 1
[2022-01-10 22:54:59,566] {local_task_job.py:264} INFO - 0 downstream tasks scheduled from follow-on schedule check
